Workbook

Sheet README
B2: iCanvas needfinding: survey data, patterns, segments and a persona
B3: Human-Computer Interaction (Tilburg University, AIR-Lab). Companion to the Week 02 (UCD & needfinding) and Week 03 (design alternatives) lectures.
A5: What this workbook is
B6: A design team is proposing iCanvas, a new lecture management system for Tilburg University. Before ideating, the team ran an anonymous online survey (needfinding) with 124 respondents about how they manage their courses in the current system (Canvas). This workbook contains the questionnaire, the raw responses and the three analysis steps that turn responses into a persona (Cooper et al., About Face): 1. analyse data to find patterns, 2. cluster user segments, 3. write a persona based on a segment.
A8: Stakeholders (Dix et al.) and who is in the sample
B9: Stakeholder type | C9: Who | D9: In this survey?
B10: Primary (use iCanvas) | C10: Students (BSc, MSc, PhD), lecturers/professors, teaching assistants | D10: Yes: 92 students, 26 lecturers/TAs
B11: Secondary (provide input / receive output) | C11: Education office, IT support, library staff; parents; education director | D11: Partly: 6 support/admin staff
B12: Tertiary (affected, no direct use) | C12: Department heads, examination board | D12: No (interviews planned)
B13: Facilitating (build / deploy) | C13: Design team, TiU IT department | D13: No (they are us)
B14: Extreme users (slide: Participants) | C14: Screen-reader / caption / dyslexia users; lecturers who use Canvas all day vs. almost never; students with 24+ h/week of work or care | D14: Yes, deliberately recruited: 22 with accessibility needs, 25 with 17+ h outside commitments
A16: Method
B17: Technique | C17: Online survey (questionnaire), the needfinding technique highlighted in green on the Week 02 slides. Interviews and observation are the planned follow-up for the surprising findings.
B18: Instrument | C18: 34 items in 5 sections: A About you (demographics, Muller et al. Table 55.1 style), B Habits (frequency, devices, features, deadline discovery), C Experience (10 Likert statements incl. one inverted duplicate pair, 7-point satisfaction, 5-point difficulty), D Ranking of 6 activities, E three open-ended grand-tour questions. See sheet 'Questionnaire'.
B19: Question rules applied | C19: No leading questions ('Is the calendar important to you?'), no 'what would you like in a tool?', no hypotheticals; ask about the last concrete time something happened (grand tour). Close-ended where the universe of answers is known and small; open-ended otherwise. Age asked in ranges and no identifiers collected (privacy).
B20: Sampling | C20: Convenience sample through CSAI/DSS mailing lists, the Mensa and the education office, topped up with deliberately recruited extreme users. Respondents are not a random sample of TiU; treat percentages as indicative.
B21: Period | C21: 8-14 September 2026 (see column 'submitted').
B22: Analysis | C22: Descriptive statistics and cross-tabulations (sheet 1-Patterns); k-means clustering on standardised behaviour + attitude features with k chosen by elbow/silhouette and interpretability (sheet 2-Segments); one persona written from the largest segment and short persona candidates for the others (sheet 3-Persona). All statistics on sheets 1 and 2 are live formulas on the Responses sheet; cluster labels and PCA coordinates are pasted values because Excel cannot run k-means.
A24: Sheet map (follows the persona process on the Week 03 slides)
B25: Sheet | C25: Contents | D25: Persona process step
B26: Questionnaire | C26: Every question, its type, answer options, numeric coding and the design rationale. | D26: Instrument
B27: Codes | C27: Lookup table code -> label -> numeric value, used by the formulas. | D27: Coding
B28: Responses | C28: 124 simulated respondents, one per row. Codes for single-choice items, 1/0 columns for multi-select items, rank 1-6 per activity, verbatim text. Derived numeric columns and the cluster label are at the right. vis.html reads this sheet. | D28: 1. Collect user needs/data
B29: 1-Patterns | C29: Sample description, habits, attitudes (means, SD, distributions), reliability of the inverted pair, rankings, cross-tabs, correlations, key patterns. | D29: 2. Analyse data to find patterns
B30: 2-Segments | C30: k selection, segment sizes, profile matrix per segment, role x segment, PCA map, segment descriptions with quotes. | D30: 3. Cluster user segments
B31: 3-Persona | C31: Full persona card for the largest segment (template layout), evidence table linking every claim to a statistic, POV statement, How-Might-We questions, persona candidates for the other segments. | D31: 4. Write a persona based on a segment
A33: Coding conventions
B34: Single choice | C34: Stored as the option code (e.g. A1_role = 'bsc'). Sheet 'Codes' maps codes to labels.
B35: Ordinal scales | C35: Frequency B1 (1 = less than once a week ... 6 = several times a day), visit length B4 (1-5), outside commitments A7 (0-4), times lost B8 (0-4) follow the numerical equivalences of Muller et al. (Table 55.2). Derived *_v columns hold the numbers.
B36: Likert C1-C10 | C36: 1 = Strongly disagree ... 7 = Strongly agree. C2 is the inverted duplicate of C1; reverse it (8 - C2) before averaging with C1. C11 satisfaction 1-7, C12 difficulty 1-5 (1 = very difficult).
B37: Multi-select | C37: One column per option, 1 = selected, 0 = not selected (A8, B2, B5, B6, B9).
B38: Ranking D1 | C38: One column per activity holding its rank, 1 = most important ... 6 = least important.
B39: Open text E1-E3 | C39: Verbatim. Empty = skipped.
A41: Data provenance (read this)
B42: The responses in this workbook are SIMULATED for teaching. They were generated (seed 2026) from six latent behavioural profiles of Canvas users at a Dutch university, with realistic noise, a straight-liner and skipped optional items, so that the three analysis steps can be demonstrated end to end. Nothing here is a statement about real Tilburg University users. The companion page vis.html reads this Responses sheet when it opens, replays the simulated submissions one by one and runs the same three analysis steps in the browser.
B44: Companion files: vis.html (reads the Responses sheet of this workbook and runs the same analysis in the browser) and user.html (the same questionnaire as a stand-alone web page for students during the lecture).

Sheet Questionnaire
A1: Questionnaire and codebook
A2: We are a design team from the Human-Computer Interaction course studying how students and staff manage their courses today, before we design a new lecture management system called iCanvas. There are no right or wrong answers; we just want to hear about your experience with the current system (Canvas). | Privacy notice shown to respondents: Anonymous and voluntary. We do not ask for your name, student number or e-mail. You can skip any question you prefer not to answer and stop at any time. Answers are used only for the needfinding exercise of the HCI course. Takes about 7 minutes.
A4: ID | B4: Section | C4: Question | D4: Type | E4: Answer options | F4: Numeric coding | G4: Column(s) in Responses | H4: Design rationale (lecture slides)
A5: A1 | B5: About you | C5: What is your main role at the university? | D5: Single choice | E5: Bachelor student [bsc] Master student [msc] PhD candidate [phd] Lecturer / professor [lecturer] Teaching assistant [ta] Support / admin staff (education office, IT, library) [staff] | F5: categorical | G5: A1_role | H5: Role first, so needs can be compared across primary stakeholders (students vs. lecturers vs. staff).
A6: A2 | B6: About you | C6: What is your age? | D6: Single choice | E6: 17-20 [17-20] 21-24 [21-24] 25-29 [25-29] 30-39 [30-39] 40-49 [40-49] 50 or older [50+] Prefer not to say [na] | F6: categorical | G6: A2_age | H6: Age in ranges rather than exact age: enough for segmentation, better for privacy (slide: consider privacy of users).
A7: A3 | B7: About you | C7: How do you identify? | D7: Single choice | E7: Female [female] Male [male] Non-binary / other [nonbinary] Prefer not to say [na] | F7: categorical | G7: A3_gender | H7: Inclusive options plus 'prefer not to say'; optional.
A8: A4 | B8: About you | C8: Which school are you mainly affiliated with? | D8: Single choice | E8: Humanities & Digital Sciences (TSHD, e.g. CSAI, DSS) [tshd] Economics & Management (TiSEM) [tisem] Social & Behavioural Sciences (TSB) [tsb] Law (TLS) [tls] Catholic Theology (TST) [tst] Other / more than one [other] | F8: categorical | G8: A4_school | H8: School as a proxy for discipline/culture of teaching.
A9: A5 | B9: About you | C9: Where did you complete most of your secondary education? | D9: Single choice | E9: In the Netherlands [nl] Elsewhere in Europe [eu] Outside Europe [noneu] Prefer not to say [na] | F9: categorical | G9: A5_origin | H9: Culture proxy that is less intrusive than nationality (slide: age, culture, abilities, technology familiarity...).
A10: A6 | B10: About you | C10: How many courses are you currently enrolled in or teaching? | D10: Single choice | E10: 1 [1] 2 [2] 3 [3] 4 [4] 5 [5] 6 or more [6+] | F10: 1 = 1, 2 = 2, 3 = 3, 4 = 4, 5 = 5, 6+ = 6 | G10: A6_courses | H10: Load: how many courses compete for attention.
A11: A7 | B11: About you | C11: Roughly how many hours per week do you spend on commitments outside your study or job (for example a paid side job, or caring for family)? | D11: Single choice | E11: None [0] 1-8 hours [1-8] 9-16 hours [9-16] 17-24 hours [17-24] More than 24 hours [25+] | F11: 0 = 0, 1-8 = 1, 9-16 = 2, 17-24 = 3, 25+ = 4 | G11: A7_hours | H11: Identifies extreme users with heavy outside commitments (jobs, caring). Ordinal, coded 0-4.
A12: A8 | B12: About you | C12: Do any of the following apply to you when you use digital tools? (select all that apply) | D12: Multiple choice | E12: None of these [none] I use a screen reader or screen magnification [screenreader] I rely on captions or transcripts for audio and video [captions] I have dyslexia or another reading-related difference [dyslexia] Fine mouse or touch control is difficult for me [motor] I prefer high contrast or reduced motion [contrast] Prefer not to say [na] | F12: 1 = selected, 0 = not | G12: A8_access__<option> | H12: Abilities/disabilities: recruits the accessibility extreme users; multi-select with exclusive 'none' and 'prefer not to say'.
A13: A9 | B13: About you | C13: How comfortable are you learning a new piece of software on your own? | D13: Scale 1-7 | E13: 1 = Not at all comfortable ... 7 = Extremely comfortable | F13: 1-7 | G13: A9_tech | H13: Technology familiarity, 7-point (Table 55.2 style).
A14: B1 | B14: How you use the current system today | C14: In a typical teaching week, how often do you open Canvas? | D14: Single choice | E14: Less than once a week [lt1] About once a week [1] 2-3 times a week [2-3] 4-6 times a week [4-6] About once a day [daily] Several times a day [several] | F14: lt1 = 1, 1 = 2, 2-3 = 3, 4-6 = 4, daily = 5, several = 6 | G14: B1_freq | H14: Frequency scale, close-ended because the universe of answers is known; coded 1-6 like Never...Very often.
A15: B2 | B15: How you use the current system today | C15: Which devices have you used to open Canvas in the last 7 days? (select all that apply) | D15: Multiple choice | E15: Laptop [laptop] Desktop computer [desktop] Smartphone, in the browser [phone_browser] Smartphone, in the Canvas app [phone_app] Tablet [tablet] | F15: 1 = selected, 0 = not | G15: B2_devices__<option> | H15: Multiple choice: more than one answer can be true (slide: types of close-ended questions).
... A35: D1 | B35: Your priorities | C35: Rank these activities by importance to you in a typical week. | D35: Ranking | E35: Finding course materials [materials] Keeping track of deadlines [deadlines] Seeing grades and feedback [grades] Communicating with instructors or students [communication] Watching lecture recordings [recordings] Organising group work [groupwork] | F35: rank 1-6 per activity | G35: D1_rank__<option> | H35: Ranking: respondents must prioritise as in real life (slide: ranking questions).
A36: E1 | B36: In your own words | C36: Think about the last time Canvas frustrated you. What were you trying to do, and what happened? | D36: Open-ended | E36: Free text | G36: E1_frustrate | H36: Open-ended grand tour, non-leading: 'the last time it frustrated you', not 'what do you dislike'.
A37: E2 | B37: In your own words | C37: Think about the last time Canvas really helped you. What were you trying to do, and what happened? | D37: Open-ended | E37: Free text | G37: E2_helped | H37: Balances E1 (assuming only frustration would be biased framing).
A38: E3 | B38: In your own words | C38: Is there anything about how you manage your courses that we haven't asked about, but you think we should know? | D38: Open-ended | E38: Free text | G38: E3_more | H38: Wrap-up question from the interview structure slide.
A40: Every question can be skipped in user.html (voluntary participation); an empty cell in Responses means the respondent skipped it. Section D asks for a full ranking.

Sheet Codes
A1: lookup | B1: question | C1: code | D1: label | E1: value
A2: A1|bsc | B2: A1 | C2: bsc | D2: Bachelor student
A3: A1|msc | B3: A1 | C3: msc | D3: Master student
A4: A1|phd | B4: A1 | C4: phd | D4: PhD candidate
A5: A1|lecturer | B5: A1 | C5: lecturer | D5: Lecturer / professor
A6: A1|ta | B6: A1 | C6: ta | D6: Teaching assistant
A7: A1|staff | B7: A1 | C7: staff | D7: Support / admin staff (education office, IT, library)
A8: A2|17-20 | B8: A2 | C8: 17-20 | D8: 17-20
A9: A2|21-24 | B9: A2 | C9: 21-24 | D9: 21-24
A10: A2|25-29 | B10: A2 | C10: 25-29 | D10: 25-29
A11: A2|30-39 | B11: A2 | C11: 30-39 | D11: 30-39
A12: A2|40-49 | B12: A2 | C12: 40-49 | D12: 40-49
A13: A2|50+ | B13: A2 | C13: 50+ | D13: 50 or older
... A28: A5|na | B28: A5 | C28: na | D28: Prefer not to say
A29: A6|1 | B29: A6 | C29: 1 | D29: 1 | E29: 1
A30: A6|2 | B30: A6 | C30: 2 | D30: 2 | E30: 2
A31: A6|3 | B31: A6 | C31: 3 | D31: 3 | E31: 3
A32: A6|4 | B32: A6 | C32: 4 | D32: 4 | E32: 4
A33: A6|5 | B33: A6 | C33: 5 | D33: 5 | E33: 5
A34: A6|6+ | B34: A6 | C34: 6+ | D34: 6 or more | E34: 6
A35: A7|0 | B35: A7 | C35: 0 | D35: None | E35: 0
A36: A7|1-8 | B36: A7 | C36: 1-8 | D36: 1-8 hours | E36: 1
A37: A7|9-16 | B37: A7 | C37: 9-16 | D37: 9-16 hours | E37: 2
A38: A7|17-24 | B38: A7 | C38: 17-24 | D38: 17-24 hours | E38: 3
A39: A7|25+ | B39: A7 | C39: 25+ | D39: More than 24 hours | E39: 4
A40: A8|none | B40: A8 | C40: none | D40: None of these
A41: A8|screenreader | B41: A8 | C41: screenreader | D41: I use a screen reader or screen magnification
A42: A8|captions | B42: A8 | C42: captions | D42: I rely on captions or transcripts for audio and video
A43: A8|dyslexia | B43: A8 | C43: dyslexia | D43: I have dyslexia or another reading-related difference
A44: A8|motor | B44: A8 | C44: motor | D44: Fine mouse or touch control is difficult for me
A45: A8|contrast | B45: A8 | C45: contrast | D45: I prefer high contrast or reduced motion
A46: A8|na | B46: A8 | C46: na | D46: Prefer not to say
A47: B1|lt1 | B47: B1 | C47: lt1 | D47: Less than once a week | E47: 1
A48: B1|1 | B48: B1 | C48: 1 | D48: About once a week | E48: 2
A49: B1|2-3 | B49: B1 | C49: 2-3 | D49: 2-3 times a week | E49: 3
A50: B1|4-6 | B50: B1 | C50: 4-6 | D50: 4-6 times a week | E50: 4
A51: B1|daily | B51: B1 | C51: daily | D51: About once a day | E51: 5
A52: B1|several | B52: B1 | C52: several | D52: Several times a day | E52: 6
A53: B2|laptop | B53: B2 | C53: laptop | D53: Laptop
A54: B2|desktop | B54: B2 | C54: desktop | D54: Desktop computer
...

Sheet Responses
A1: id | B1: submitted | C1: A1_role | D1: A2_age | E1: A3_gender | F1: A4_school | G1: A5_origin | H1: A6_courses | I1: A7_hours | J1: A8_access__none | K1: A8_access__screenreader | L1: A8_access__captions | M1: A8_access__dyslexia | N1: A8_access__motor | O1: A8_access__contrast | P1: A8_access__na | Q1: A9_tech | R1: B1_freq | S1: B2_devices__laptop | T1: B2_devices__desktop | U1: B2_devices__phone_browser | V1: B2_devices__phone_app | W1: B2_devices__tablet | X1: B3_primary | Y1: B4_session | Z1: B5_features__announcements | AA1: B5_features__assignments | AB1: B5_features__grades | AC1: B5_features__modules | AD1: B5_features__calendar | AE1: B5_features__inbox | AF1: B5_features__discussions | AG1: B5_features__quizzes | AH1: B5_features__recordings | AI1: B5_features__groups | AJ1: B5_features__syllabus | AK1: B5_features__none | AL1: B6_deadline__canvas_cal | AM1: B6_deadline__email | AN1: B6_deadline__push | AO1: B6_deadline__in_class | AP1: B6_deadline__peer | AQ1: B6_deadline__syllabus | AR1: B6_deadline__own_cal | AS1: B6_deadline__late | AT1: B7_notif | AU1: B8_lost | AV1: B9_tools__paper | AW1: B9_tools__calendar | AX1: B9_tools__notes | AY1: B9_tools__chat | AZ1: B9_tools__email | BA1: B9_tools__none | BB1: C1_find_fast | BC1: C2_find_slow | BD1: C3_notif_useful | BE1: C4_notif_noise | BF1: C5_mobile | BG1: C6_consistent | BH1: C7_uptodate | BI1: C8_confident | BJ1: C9_accessible | BK1: C10_group | BL1: C11_satisfaction | BM1: C12_ease | BN1: D1_rank__materials | BO1: D1_rank__deadlines | BP1: D1_rank__grades | BQ1: D1_rank__communication | BR1: D1_rank__recordings | BS1: D1_rank__groupwork | BT1: E1_frustrate | BU1: E2_helped | BV1: E3_more | BW1: freq_v | BX1: session_v | BY1: hours_v | BZ1: lost_v | CA1: courses_v | CB1: phone_primary | CC1: C2_rev | CD1: Segment | CE1: PC1 | CF1: PC2
A2: R001 | B2: 2026-09-08 14:10 | C2: lecturer | D2: 30-39 | E2: female | F2: tisem | G2: nl | H2: 2 | I2: 1-8 | J2: 1 | K2: 0 | L2: 0 | M2: 0 | N2: 0 | O2: 0 | P2: 0 | Q2: 6 | R2: several | S2: 1 | T2: 1 | U2: 0 | V2: 0 | W2: 0 | X2: desktop | Y2: gt30 | Z2: 1 | AA2: 1 | AB2: 1 | AC2: 1 | AD2: 1 | AE2: 0 | AF2: 1 | AG2: 0 | AH2: 0 | AI2: 0 | AJ2: 1 | AK2: 0 | AL2: 0 | AM2: 0 | AN2: 0 | AO2: 0 | AP2: 1 | AQ2: 0 | AR2: 1 | AS2: 0 | AT2: inapp | AU2: 1 | AV2: 1 | AW2: 1 | AX2: 0 | AY2: 0 | AZ2: 1 | BA2: 0 | BB2: 4 | BC2: 4 | BD2: 5 | BE2: 7 | BF2: 3 | BG2: 4 | BH2: 4 | BI2: 5 | BJ2: 5 | BK2: 3 | BL2: 5 | BM2: 5 | BN2: 2 | BO2: 4 | BP2: 1 | BQ2: 3 | BR2: 6 | BS2: 5 | BT2: Extending a deadline for three students with an arrangement means editing the assignment, adding a section override, and hoping the dates don't shift for everyone else. | BU2: Students see their grades and feedback at the same moment, no more 200 emails. | BW2: =IF($R2="","",INDEX(Codes!$E$2:$E$108,MATCH("B1|"&$R2,Codes!$A$2:$A$108,0))) -> 6 | BX2: =IF($Y2="","",INDEX(Codes!$E$2:$E$108,MATCH("B4|"&$Y2,Codes!$A$2:$A$108,0))) -> 5 | BY2: =IF($I2="","",INDEX(Codes!$E$2:$E$108,MATCH("A7|"&$I2,Codes!$A$2:$A$108,0))) -> 1 | BZ2: =IF($AU2="","",INDEX(Codes!$E$2:$E$108,MATCH("B8|"&$AU2,Codes!$A$2:$A$108,0))) -> 1 | CA2: =IF($H2="","",INDEX(Codes!$E$2:$E$108,MATCH("A6|"&$H2,Codes!$A$2:$A$108,0))) -> 2 | CB2: =IF($X2="","",IF($X2="phone",1,0)) -> 0 | CC2: =IF($BC2="","",8-$BC2) -> 4 | CD2: S4 Power Instructors | CE2: -1.762 | CF2: 1.714
A3: R002 | B3: 2026-09-08 15:54 | C3: msc | D3: 21-24 | E3: male | F3: tls | G3: eu | H3: 3 | I3: 0 | J3: 0 | K3: 0 | L3: 1 | M3: 0 | N3: 0 | O3: 0 | P3: 0 | Q3: 6 | R3: 4-6 | S3: 1 | T3: 0 | U3: 0 | V3: 1 | W3: 0 | X3: laptop | Y3: gt30 | Z3: 0 | AA3: 1 | AB3: 0 | AC3: 1 | AD3: 1 | AE3: 0 | AF3: 1 | AG3: 0 | AH3: 0 | AI3: 0 | AJ3: 0 | AK3: 0 | AL3: 0 | AM3: 0 | AN3: 0 | AO3: 0 | AP3: 0 | AQ3: 0 | AR3: 1 | AS3: 0 | AT3: push | AU3: 2-3 | AV3: 1 | AW3: 0 | AX3: 1 | AY3: 1 | AZ3: 0 | BA3: 0 | BB3: 2 | BC3: 6 | BD3: 2 | BE3: 4 | BF3: 3 | BG3: 2 | BH3: 3 | BI3: 6 | BJ3: 4 | BK3: 3 | BL3: 4 | BM3: 5 | BN3: 1 | BO3: 3 | BP3: 4 | BQ3: 6 | BR3: 2 | BS3: 5 | BT3: I was looking for the reading list for week 4 of Linear Algebra. One lecturer puts readings in Modules, another in Files, another in a PDF under Syllabus. I spent 15 minutes clicking around | BU3: Not much, it does the job. | BV3: A proper reading list with status (read / to read) would be great. | BW3: =IF($R3="","",INDEX(Codes!$E$2:$E$108,MATCH("B1|"&$R3,Codes!$A$2:$A$108,0))) -> 4 | BX3: =IF($Y3="","",INDEX(Codes!$E$2:$E$108,MATCH("B4|"&$Y3,Codes!$A$2:$A$108,0))) -> 5 | BY3: =IF($I3="","",INDEX(Codes!$E$2:$E$108,MATCH("A7|"&$I3,Codes!$A$2:$A$108,0))) -> 0 | BZ3: =IF($AU3="","",INDEX(Codes!$E$2:$E$108,MATCH("B8|"&$AU3,Codes!$A$2:$A$108,0))) -> 2 | CA3: =IF($H3="","",INDEX(Codes!$E$2:$E$108,MATCH("A6|"&$H3,Codes!$A$2:$A$108,0))) -> 3 | CB3: =IF($X3="","",IF($X3="phone",1,0)) -> 0 | CC3: =IF($BC3="","",8-$BC3) -> 2 | CD3: S2 Structured Scholars | CE3: 2.285 | CF3: 2.185
A4: R003 | B4: 2026-09-08 16:10 | C4: phd | D4: 30-39 | E4: female | F4: other | G4: eu | H4: 1 | I4: 0 | J4: 1 | K4: 0 | L4: 0 | M4: 0 | N4: 0 | O4: 0 | P4: 0 | Q4: 5 | R4: daily | S4: 1 | T4: 1 | U4: 0 | V4: 0 | W4: 0 | X4: laptop | Y4: 5-15 | Z4: 1 | AA4: 1 | AB4: 0 | AC4: 1 | AD4: 0 | AE4: 0 | AF4: 0 | AG4: 0 | AH4: 1 | AI4: 0 | AJ4: 0 | AK4: 0 | AL4: 1 | AM4: 1 | AN4: 0 | AO4: 1 | AP4: 1 | AQ4: 1 | AR4: 1 | AS4: 0 | AT4: email | AU4: 2-3 | AV4: 0 | AW4: 1 | AX4: 1 | AY4: 1 | AZ4: 0 | BA4: 0 | BB4: 3 | BC4: 3 | BD4: 6 | BE4: 4 | BF4: 4 | BG4: 3 | BH4: 6 | BI4: 6 | BJ4: 6 | BK4: 6 | BL4: 4 | BM4: 4 | BN4: 1 | BO4: 3 | BP4: 4 | BQ4: 6 | BR4: 2 | BS4: 5 | BT4: The syllabus page was empty in 3 of my 4 courses. The actual course guide was a PDF somewhere in Files. | BU4: The Modules page for Qualitative Methods was set up week by week with readings, slides and the recording in one place. That is how every course should look. | BV4: I use Notion for everything and Canvas is just the place where files live. | BW4: =IF($R4="","",INDEX(Codes!$E$2:$E$108,MATCH("B1|"&$R4,Codes!$A$2:$A$108,0))) -> 5 | BX4: =IF($Y4="","",INDEX(Codes!$E$2:$E$108,MATCH("B4|"&$Y4,Codes!$A$2:$A$108,0))) -> 3 | BY4: =IF($I4="","",INDEX(Codes!$E$2:$E$108,MATCH("A7|"&$I4,Codes!$A$2:$A$108,0))) -> 0 | BZ4: =IF($AU4="","",INDEX(Codes!$E$2:$E$108,MATCH("B8|"&$AU4,Codes!$A$2:$A$108,0))) -> 2 | CA4: =IF($H4="","",INDEX(Codes!$E$2:$E$108,MATCH("A6|"&$H4,Codes!$A$2:$A$108,0))) -> 1 | CB4: =IF($X4="","",IF($X4="phone",1,0)) -> 0 | CC4: =IF($BC4="","",8-$BC4) -> 5 | CD4: S2 Structured Scholars | CE4: 0.003 | CF4: 2.569
A5: R004 | B5: 2026-09-08 16:21 | C5: lecturer | D5: 40-49 | E5: male | F5: tshd | G5: nl | H5: 3 | I5: 9-16 | J5: 1 | K5: 0 | L5: 0 | M5: 0 | N5: 0 | O5: 0 | P5: 0 | Q5: 3 | R5: 1 | S5: 1 | T5: 1 | U5: 0 | V5: 0 | W5: 1 | X5: desktop | Y5: 5-15 | Z5: 0 | AA5: 0 | AB5: 0 | AC5: 0 | AD5: 0 | AE5: 0 | AF5: 0 | AG5: 0 | AH5: 1 | AI5: 1 | AJ5: 0 | AK5: 0 | AL5: 0 | AM5: 0 | AN5: 0 | AO5: 0 | AP5: 0 | AQ5: 0 | AR5: 1 | AS5: 0 | AT5: email | AU5: 2-3 | AV5: 0 | AW5: 1 | AX5: 0 | AY5: 0 | AZ5: 1 | BA5: 0 | BB5: 3 | BC5: 5 | BD5: 2 | BE5: 4 | BF5: 3 | BG5: 2 | BH5: 4 | BI5: 2 | BJ5: 2 | BK5: 5 | BL5: 1 | BM5: 1 | BN5: 1 | BO5: 2 | BP5: 4 | BQ5: 3 | BR5: 5 | BS5: 6 | BT5: Uploading a 200 MB recording failed twice without any message. | BU5: Grades were visible to students without me having to send them individually | BV5: Training once a year is not enough; I need help at the moment I am doing it. | BW5: =IF($R5="","",INDEX(Codes!$E$2:$E$108,MATCH("B1|"&$R5,Codes!$A$2:$A$108,0))) -> 2 | BX5: =IF($Y5="","",INDEX(Codes!$E$2:$E$108,MATCH("B4|"&$Y5,Codes!$A$2:$A$108,0))) -> 3 | BY5: =IF($I5="","",INDEX(Codes!$E$2:$E$108,MATCH("A7|"&$I5,Codes!$A$2:$A$108,0))) -> 2 | BZ5: =IF($AU5="","",INDEX(Codes!$E$2:$E$108,MATCH("B8|"&$AU5,Codes!$A$2:$A$108,0))) -> 2 | CA5: =IF($H5="","",INDEX(Codes!$E$2:$E$108,MATCH("A6|"&$H5,Codes!$A$2:$A$108,0))) -> 3 | CB5: =IF($X5="","",IF($X5="phone",1,0)) -> 0 | CC5: =IF($BC5="","",8-$BC5) -> 3 | CD5: S5 Reluctant Instructors | CE5: 3.71 | CF5: -2.842
A6: R005 | B6: 2026-09-08 18:55 | C6: msc | D6: 21-24 | E6: female | F6: other | G6: nl | H6: 2 | I6: 0 | J6: 1 | K6: 0 | L6: 0 | M6: 0 | N6: 0 | O6: 0 | P6: 0 | Q6: 6 | R6: 4-6 | S6: 1 | T6: 0 | U6: 0 | V6: 0 | W6: 1 | X6: laptop | Y6: gt30 | Z6: 0 | AA6: 1 | AB6: 1 | AC6: 1 | AD6: 1 | AE6: 1 | AF6: 1 | AG6: 0 | AH6: 1 | AI6: 1 | AJ6: 1 | AK6: 0 | AL6: 1 | AM6: 0 | AN6: 0 | AO6: 1 | AP6: 0 | AQ6: 0 | AR6: 1 | AS6: 0 | AT6: inapp | AU6: 1 | AV6: 0 | AW6: 1 | AX6: 0 | AY6: 1 | AZ6: 0 | BA6: 0 | BB6: 3 | BC6: 6 | BD6: 3 | BE6: 5 | BF6: 4 | BG6: 2 | BH6: 5 | BI6: 4 | BJ6: 5 | BK6: 4 | BL6: 2 | BM6: 5 | BN6: 3 | BO6: 2 | BP6: 4 | BQ6: 5 | BR6: 1 | BS6: 6 | BT6: Group project files were spread across Canvas groups, Google Drive and WhatsApp. Canvas Collaborations didn't work with our university accounts. | BW6: =IF($R6="","",INDEX(Codes!$E$2:$E$108,MATCH("B1|"&$R6,Codes!$A$2:$A$108,0))) -> 4 | BX6: =IF($Y6="","",INDEX(Codes!$E$2:$E$108,MATCH("B4|"&$Y6,Codes!$A$2:$A$108,0))) -> 5 | BY6: =IF($I6="","",INDEX(Codes!$E$2:$E$108,MATCH("A7|"&$I6,Codes!$A$2:$A$108,0))) -> 0 | BZ6: =IF($AU6="","",INDEX(Codes!$E$2:$E$108,MATCH("B8|"&$AU6,Codes!$A$2:$A$108,0))) -> 1 | CA6: =IF($H6="","",INDEX(Codes!$E$2:$E$108,MATCH("A6|"&$H6,Codes!$A$2:$A$108,0))) -> 2 | CB6: =IF($X6="","",IF($X6="phone",1,0)) -> 0 | CC6: =IF($BC6="","",8-$BC6) -> 2 | CD6: S2 Structured Scholars | CE6: 1.942 | CF6: 1.078
A7: R006 | B7: 2026-09-08 19:15 | C7: msc | D7: 25-29 | E7: male | F7: tisem | G7: noneu | H7: 3 | I7: 9-16 | J7: 1 | K7: 0 | L7: 0 | M7: 0 | N7: 0 | O7: 0 | P7: 0 | Q7: 6 | R7: daily | S7: 1 | T7: 0 | U7: 0 | V7: 0 | W7: 0 | X7: laptop | Y7: gt30 | Z7: 1 | AA7: 1 | AB7: 0 | AC7: 1 | AD7: 0 | AE7: 0 | AF7: 0 | AG7: 0 | AH7: 1 | AI7: 0 | AJ7: 0 | AK7: 0 | AL7: 0 | AM7: 1 | AN7: 0 | AO7: 0 | AP7: 1 | AQ7: 0 | AR7: 0 | AS7: 0 | AT7: off | AU7: 2-3 | AV7: 0 | AW7: 1 | AX7: 1 | AY7: 1 | AZ7: 0 | BA7: 0 | BB7: 3 | BC7: 5 | BD7: 4 | BE7: 4 | BF7: 3 | BG7: 4 | BH7: 4 | BI7: 5 | BJ7: 6 | BK7: 5 | BL7: 4 | BM7: 4 | BN7: 1 | BO7: 3 | BP7: 4 | BQ7: 5 | BR7: 2 | BS7: 6 | BT7: trying to see the deadlines of all courses in one view. Exported the calendar feed to Google Calendar, but half the assignments had no dates so they never appeared. | BU7: The calendar feed into Google Calendar, once the lecturer actually dated everything. | BV7: A proper reading list with status (read / to read) would be great. | BW7: =IF($R7="","",INDEX(Codes!$E$2:$E$108,MATCH("B1|"&$R7,Codes!$A$2:$A$108,0))) -> 5 | BX7: =IF($Y7="","",INDEX(Codes!$E$2:$E$108,MATCH("B4|"&$Y7,Codes!$A$2:$A$108,0))) -> 5 | BY7: =IF($I7="","",INDEX(Codes!$E$2:$E$108,MATCH("A7|"&$I7,Codes!$A$2:$A$108,0))) -> 2 | BZ7: =IF($AU7="","",INDEX(Codes!$E$2:$E$108,MATCH("B8|"&$AU7,Codes!$A$2:$A$108,0))) -> 2 | CA7: =IF($H7="","",INDEX(Codes!$E$2:$E$108,MATCH("A6|"&$H7,Codes!$A$2:$A$108,0))) -> 3 | CB7: =IF($X7="","",IF($X7="phone",1,0)) -> 0 | CC7: =IF($BC7="","",8-$BC7) -> 3 | CD7: S2 Structured Scholars | CE7: 0.922 | CF7: 1.664
A8: R007 | B8: 2026-09-08 19:34 | C8: bsc | D8: 17-20 | E8: male | F8: tshd | G8: nl | H8: 5 | I8: 1-8 | J8: 0 | K8: 0 | L8: 1 | M8: 0 | N8: 0 | O8: 0 | P8: 0 | Q8: 5 | R8: several | S8: 1 | T8: 0 | U8: 0 | V8: 1 | W8: 0 | X8: phone | Y8: lt2 | Z8: 1 | AA8: 1 | AB8: 1 | AC8: 1 | AD8: 0 | AE8: 1 | AF8: 0 | AG8: 0 | AH8: 0 | AI8: 1 | AJ8: 0 | AK8: 0 | AL8: 0 | AM8: 0 | AN8: 1 | AO8: 0 | AP8: 0 | AQ8: 0 | AR8: 0 | AS8: 0 | AT8: inapp | AU8: 2-3 | AV8: 0 | AW8: 0 | AX8: 1 | AY8: 1 | AZ8: 0 | BA8: 0 | BB8: 3 | BC8: 5 | BD8: 5 | BE8: 5 | BF8: 3 | BG8: 4 | BH8: 2 | BI8: 4 | BJ8: 5 | BK8: 4 | BL8: 3 | BM8: 4 | BN8: 3 | BO8: 1 | BP8: 2 | BQ8: 4 | BR8: 5 | BS8: 6 | BT8: Checking my grade for the Deep Learning midterm: the number was there but the class average was hidden, so I couldn't tell if a 6.1 was good or bad. | BU8: The announcement about the room change came right before the lecture; I would have gone to the wrong building. | BW8: =IF($R8="","",INDEX(Codes!$E$2:$E$108,MATCH("B1|"&$R8,Codes!$A$2:$A$108,0))) -> 6 | BX8: =IF($Y8="","",INDEX(Codes!$E$2:$E$108,MATCH("B4|"&$Y8,Codes!$A$2:$A$108,0))) -> 1 | BY8: =IF($I8="","",INDEX(Codes!$E$2:$E$108,MATCH("A7|"&$I8,Codes!$A$2:$A$108,0))) -> 1 | BZ8: =IF($AU8="","",INDEX(Codes!$E$2:$E$108,MATCH("B8|"&$AU8,Codes!$A$2:$A$108,0))) -> 2 | CA8: =IF($H8="","",INDEX(Codes!$E$2:$E$108,MATCH("A6|"&$H8,Codes!$A$2:$A$108,0))) -> 5 | CB8: =IF($X8="","",IF($X8="phone",1,0)) -> 1 | CC8: =IF($BC8="","",8-$BC8) -> 3 | CD8: S1 Deadline Sprinters | CE8: -1.973 | CF8: -2.043
A9: R008 | B9: 2026-09-08 20:46 | C9: bsc | D9: 25-29 | E9: male | F9: tshd | G9: nl | H9: 5 | I9: 17-24 | J9: 1 | K9: 0 | L9: 0 | M9: 0 | N9: 0 | O9: 0 | P9: 0 | Q9: 4 | R9: 4-6 | S9: 1 | T9: 0 | U9: 1 | V9: 1 | W9: 0 | X9: laptop | Y9: 5-15 | Z9: 1 | AA9: 1 | AB9: 1 | AC9: 1 | AD9: 1 | AE9: 0 | AF9: 0 | AG9: 0 | AH9: 1 | AI9: 1 | AJ9: 0 | AK9: 0 | AL9: 1 | AM9: 1 | AN9: 0 | AO9: 0 | AP9: 1 | AQ9: 0 | AR9: 0 | AS9: 0 | AT9: email | AU9: 1 | AV9: 0 | AW9: 1 | AX9: 0 | AY9: 1 | AZ9: 1 | BA9: 0 | BB9: 5 | BC9: 3 | BD9: 3 | BE9: 3 | BF9: 5 | BG9: 3 | BH9: 6 | BI9: 6 | BJ9: 5 | BK9: 3 | BL9: 6 | BM9: 4 | BN9: 3 | BO9: 2 | BP9: 4 | BQ9: 5 | BR9: 1 | BS9: 6 | BT9: Came back after a week of night shifts and the Developmental Psychology module for that week had 14 items. Which of these do I actually need before the tutorial? | BU9: Being able to submit from my phone during a break. | BW9: =IF($R9="","",INDEX(Codes!$E$2:$E$108,MATCH("B1|"&$R9,Codes!$A$2:$A$108,0))) -> 4 | BX9: =IF($Y9="","",INDEX(Codes!$E$2:$E$108,MATCH("B4|"&$Y9,Codes!$A$2:$A$108,0))) -> 3 | BY9: =IF($I9="","",INDEX(Codes!$E$2:$E$108,MATCH("A7|"&$I9,Codes!$A$2:$A$108,0))) -> 3 | BZ9: =IF($AU9="","",INDEX(Codes!$E$2:$E$108,MATCH("B8|"&$AU9,Codes!$A$2:$A$108,0))) -> 1 | CA9: =IF($H9="","",INDEX(Codes!$E$2:$E$108,MATCH("A6|"&$H9,Codes!$A$2:$A$108,0))) -> 5 | CB9: =IF($X9="","",IF($X9="phone",1,0)) -> 0 | CC9: =IF($BC9="","",8-$BC9) -> 5 | CD9: S3 Overloaded Jugglers | CE9: 0.031 | CF9: 0.529
A10: R009 | B10: 2026-09-08 21:06 | C10: lecturer | D10: 40-49 | E10: male | F10: tisem | G10: noneu | H10: 1 | I10: 9-16 | J10: 0 | K10: 0 | L10: 1 | M10: 0 | N10: 0 | O10: 0 | P10: 0 | Q10: 3 | R10: 1 | S10: 1 | T10: 0 | U10: 1 | V10: 0 | W10: 0 | X10: desktop | Y10: 5-15 | Z10: 1 | AA10: 0 | AB10: 0 | AC10: 1 | AD10: 0 | AE10: 0 | AF10: 0 | AG10: 0 | AH10: 0 | AI10: 0 | AJ10: 0 | AK10: 0 | AL10: 0 | AM10: 0 | AN10: 0 | AO10: 0 | AP10: 1 | AQ10: 1 | AR10: 1 | AS10: 0 | AT10: email | AU10: 2-3 | AV10: 0 | AW10: 1 | AX10: 0 | AY10: 0 | AZ10: 1 | BA10: 0 | BB10: 2 | BC10: 5 | BD10: 5 | BE10: 4 | BF10: 6 | BG10: 1 | BH10: 2 | BI10: 2 | BJ10: 4 | BK10: 1 | BL10: 2 | BM10: 1 | BN10: 1 | BO10: 3 | BP10: 4 | BQ10: 2 | BR10: 5 | BS10: 6 | BT10: I do not use the calendar; my secretary keeps my agenda. But students expect the deadlines to be in Canvas, so there is always a mismatch. | BU10: Nothing comes to mind, honestly. | BW10: =IF($R10="","",INDEX(Codes!$E$2:$E$108,MATCH("B1|"&$R10,Codes!$A$2:$A$108,0))) -> 2 | BX10: =IF($Y10="","",INDEX(Codes!$E$2:$E$108,MATCH("B4|"&$Y10,Codes!$A$2:$A$108,0))) -> 3 | BY10: =IF($I10="","",INDEX(Codes!$E$2:$E$108,MATCH("A7|"&$I10,Codes!$A$2:$A$108,0))) -> 2 | BZ10: =IF($AU10="","",INDEX(Codes!$E$2:$E$108,MATCH("B8|"&$AU10,Codes!$A$2:$A$108,0))) -> 2 | CA10: =IF($H10="","",INDEX(Codes!$E$2:$E$108,MATCH("A6|"&$H10,Codes!$A$2:$A$108,0))) -> 1 | CB10: =IF($X10="","",IF($X10="phone",1,0)) -> 0 | CC10: =IF($BC10="","",8-$BC10) -> 3 | CD10: S5 Reluctant Instructors | CE10: 3.895 | CF10: -2.756
A11: R010 | B11: 2026-09-08 21:35 | C11: bsc | D11: 17-20 | E11: female | F11: tshd | G11: noneu | H11: 4 | I11: 9-16 | J11: 1 | K11: 0 | L11: 0 | M11: 0 | N11: 0 | O11: 0 | P11: 0 | Q11: 5 | R11: several | S11: 1 | T11: 0 | U11: 0 | V11: 1 | W11: 0 | X11: phone | Y11: lt2 | Z11: 1 | AA11: 1 | AB11: 1 | AC11: 1 | AD11: 1 | AE11: 0 | AF11: 1 | AG11: 1 | AH11: 0 | AI11: 0 | AJ11: 0 | AK11: 0 | AL11: 0 | AM11: 1 | AN11: 1 | AO11: 0 | AP11: 1 | AQ11: 1 | AR11: 0 | AS11: 0 | AT11: push | AU11: 2-3 | AV11: 0 | AW11: 0 | AX11: 0 | AY11: 1 | AZ11: 0 | BA11: 0 | BB11: 3 | BC11: 5 | BD11: 5 | BE11: 4 | BF11: 1 | BG11: 4 | BH11: 4 | BI11: 5 | BJ11: 4 | BK11: 3 | BL11: 5 | BM11: 5 | BN11: 5 | BO11: 1 | BP11: 2 | BQ11: 3 | BR11: 4 | BS11: 6 | BT11: Discussion post for Philosophy of Mind counted as an assignment, so it showed up in my grades as 0 for a week and freaked me out. | BW11: =IF($R11="","",INDEX(Codes!$E$2:$E$108,MATCH("B1|"&$R11,Codes!$A$2:$A$108,0))) -> 6 | BX11: =IF($Y11="","",INDEX(Codes!$E$2:$E$108,MATCH("B4|"&$Y11,Codes!$A$2:$A$108,0))) -> 1 | BY11: =IF($I11="","",INDEX(Codes!$E$2:$E$108,MATCH("A7|"&$I11,Codes!$A$2:$A$108,0))) -> 2 | BZ11: =IF($AU11="","",INDEX(Codes!$E$2:$E$108,MATCH("B8|"&$AU11,Codes!$A$2:$A$108,0))) -> 2 | CA11: =IF($H11="","",INDEX(Codes!$E$2:$E$108,MATCH("A6|"&$H11,Codes!$A$2:$A$108,0))) -> 4 | CB11: =IF($X11="","",IF($X11="phone",1,0)) -> 1 | CC11: =IF($BC11="","",8-$BC11) -> 3 | CD11: S1 Deadline Sprinters | CE11: -3.062 | CF11: -1.57
A12: R011 | B12: 2026-09-08 23:14 | C12: msc | D12: 17-20 | E12: female | F12: tisem | G12: nl | H12: 4 | I12: 9-16 | J12: 1 | K12: 0 | L12: 0 | M12: 0 | N12: 0 | O12: 0 | P12: 0 | Q12: 7 | R12: several | S12: 1 | T12: 1 | U12: 0 | V12: 1 | W12: 0 | X12: phone | Y12: 2-5 | Z12: 1 | AA12: 1 | AB12: 1 | AC12: 0 | AD12: 1 | AE12: 1 | AF12: 0 | AG12: 1 | AH12: 1 | AI12: 0 | AJ12: 0 | AK12: 0 | AL12: 1 | AM12: 0 | AN12: 1 | AO12: 0 | AP12: 0 | AQ12: 0 | AR12: 0 | AS12: 1 | AT12: push | AU12: 0 | AV12: 0 | AW12: 1 | AX12: 0 | AY12: 1 | AZ12: 0 | BA12: 0 | BB12: 4 | BC12: 4 | BD12: 5 | BE12: 6 | BF12: 4 | BG12: 6 | BH12: 5 | BI12: 4 | BJ12: 6 | BK12: 3 | BL12: 4 | BM12: 3 | BN12: 3 | BO12: 1 | BP12: 2 | BQ12: 4 | BR12: 5 | BS12: 6 | BT12: Wanted to see what is due this week across all my courses. The dashboard cards each show something different and the calendar only shows things the teacher put a date on. | BV12: I basically live in WhatsApp groups for each course; that's where the real info is. | BW12: =IF($R12="","",INDEX(Codes!$E$2:$E$108,MATCH("B1|"&$R12,Codes!$A$2:$A$108,0))) -> 6 | BX12: =IF($Y12="","",INDEX(Codes!$E$2:$E$108,MATCH("B4|"&$Y12,Codes!$A$2:$A$108,0))) -> 2 | BY12: =IF($I12="","",INDEX(Codes!$E$2:$E$108,MATCH("A7|"&$I12,Codes!$A$2:$A$108,0))) -> 2 | BZ12: =IF($AU12="","",INDEX(Codes!$E$2:$E$108,MATCH("B8|"&$AU12,Codes!$A$2:$A$108,0))) -> 0 | CA12: =IF($H12="","",INDEX(Codes!$E$2:$E$108,MATCH("A6|"&$H12,Codes!$A$2:$A$108,0))) -> 4 | CB12: =IF($X12="","",IF($X12="phone",1,0)) -> 1 | CC12: =IF($BC12="","",8-$BC12) -> 4 | CD12: S1 Deadline Sprinters | CE12: -2.868 | CF12: -0.913
A13: R012 | B13: 2026-09-09 00:21 | C13: msc | D13: 25-29 | E13: male | F13: tshd | G13: nl | H13: 4 | I13: 17-24 | J13: 1 | K13: 0 | L13: 0 | M13: 0 | N13: 0 | O13: 0 | P13: 0 | Q13: 4 | R13: 2-3 | S13: 1 | T13: 0 | U13: 0 | V13: 1 | W13: 0 | X13: phone | Y13: 15-30 | Z13: 0 | AA13: 1 | AB13: 1 | AC13: 1 | AD13: 0 | AE13: 0 | AF13: 1 | AG13: 0 | AH13: 1 | AI13: 1 | AJ13: 0 | AK13: 0 | AL13: 0 | AM13: 0 | AN13: 0 | AO13: 0 | AP13: 0 | AQ13: 0 | AR13: 1 | AS13: 0 | AT13: email | AU13: 4-6 | AV13: 0 | AW13: 1 | AX13: 0 | AY13: 1 | AZ13: 0 | BA13: 0 | BB13: 4 | BC13: 2 | BD13: 4 | BE13: 5 | BF13: 4 | BG13: 2 | BH13: 3 | BI13: 3 | BJ13: 4 | BK13: 3 | BL13: 3 | BM13: 4 | BN13: 4 | BO13: 1 | BP13: 3 | BQ13: 5 | BR13: 2 | BS13: 6 | BT13: Notification emails arrive during my working hours and are gone from my head by the evening. I have missed two small deadlines that way. | BU13: Seeing on Sunday evening exactly what is due in the coming week, at least for the courses that date their assignments. | BV13: a weekly digest of what changed and what is due. | BW13: =IF($R13="","",INDEX(Codes!$E$2:$E$108,MATCH("B1|"&$R13,Codes!$A$2:$A$108,0))) -> 3 | BX13: =IF($Y13="","",INDEX(Codes!$E$2:$E$108,MATCH("B4|"&$Y13,Codes!$A$2:$A$108,0))) -> 4 | BY13: =IF($I13="","",INDEX(Codes!$E$2:$E$108,MATCH("A7|"&$I13,Codes!$A$2:$A$108,0))) -> 3 | BZ13: =IF($AU13="","",INDEX(Codes!$E$2:$E$108,MATCH("B8|"&$AU13,Codes!$A$2:$A$108,0))) -> 3 | CA13: =IF($H13="","",INDEX(Codes!$E$2:$E$108,MATCH("A6|"&$H13,Codes!$A$2:$A$108,0))) -> 4 | CB13: =IF($X13="","",IF($X13="phone",1,0)) -> 1 | CC13: =IF($BC13="","",8-$BC13) -> 6 | CD13: S3 Overloaded Jugglers | CE13: 0.177 | CF13: -2.707
A14: R013 | B14: 2026-09-09 01:46 | C14: phd | D14: 21-24 | E14: na | F14: tls | G14: nl | H14: 2 | I14: 0 | J14: 1 | K14: 0 | L14: 0 | M14: 0 | N14: 0 | O14: 0 | P14: 0 | Q14: 5 | R14: several | S14: 1 | T14: 0 | U14: 1 | V14: 0 | W14: 0 | X14: laptop | Y14: 15-30 | Z14: 1 | AA14: 1 | AB14: 0 | AC14: 1 | AD14: 0 | AE14: 0 | AF14: 0 | AG14: 0 | AH14: 0 | AI14: 1 | AJ14: 0 | AK14: 0 | AL14: 0 | AM14: 0 | AN14: 0 | AO14: 0 | AP14: 1 | AQ14: 0 | AR14: 0 | AS14: 0 | AT14: email | AU14: 1 | AV14: 0 | AW14: 1 | AX14: 1 | AY14: 1 | AZ14: 1 | BA14: 0 | BB14: 4 | BC14: 4 | BD14: 4 | BE14: 4 | BF14: 4 | BG14: 4 | BH14: 4 | BI14: 4 | BJ14: 4 | BK14: 4 | BL14: 5 | BM14: 3 | BN14: 1 | BO14: 3 | BP14: 4 | BQ14: 5 | BR14: 2 | BS14: 6 | BT14: nothing really | BW14: =IF($R14="","",INDEX(Codes!$E$2:$E$108,MATCH("B1|"&$R14,Codes!$A$2:$A$108,0))) -> 6 | BX14: =IF($Y14="","",INDEX(Codes!$E$2:$E$108,MATCH("B4|"&$Y14,Codes!$A$2:$A$108,0))) -> 4 | BY14: =IF($I14="","",INDEX(Codes!$E$2:$E$108,MATCH("A7|"&$I14,Codes!$A$2:$A$108,0))) -> 0 | BZ14: =IF($AU14="","",INDEX(Codes!$E$2:$E$108,MATCH("B8|"&$AU14,Codes!$A$2:$A$108,0))) -> 1 | CA14: =IF($H14="","",INDEX(Codes!$E$2:$E$108,MATCH("A6|"&$H14,Codes!$A$2:$A$108,0))) -> 2 | CB14: =IF($X14="","",IF($X14="phone",1,0)) -> 0 | CC14: =IF($BC14="","",8-$BC14) -> 4 | CD14: S2 Structured Scholars | CE14: 0.791 | CF14: 1.322
A15: R014 | B15: 2026-09-09 02:09 | C15: bsc | D15: 21-24 | E15: male | F15: tisem | G15: nl | H15: 6+ | I15: 17-24 | J15: 0 | K15: 1 | L15: 0 | M15: 0 | N15: 0 | O15: 0 | P15: 0 | Q15: 5 | R15: daily | S15: 1 | T15: 0 | U15: 1 | V15: 0 | W15: 0 | X15: laptop | Y15: gt30 | Z15: 1 | AA15: 0 | AB15: 0 | AC15: 1 | AD15: 1 | AE15: 0 | AF15: 0 | AG15: 0 | AH15: 1 | AI15: 0 | AJ15: 0 | AK15: 0 | AL15: 0 | AM15: 0 | AN15: 0 | AO15: 0 | AP15: 1 | AQ15: 0 | AR15: 1 | AS15: 0 | AT15: email | AU15: 2-3 | AV15: 0 | AW15: 1 | AX15: 1 | AY15: 1 | AZ15: 1 | BA15: 0 | BB15: 1 | BC15: 6 | BD15: 3 | BE15: 4 | BF15: 2 | BG15: 1 | BH15: 5 | BI15: 5 | BJ15: 1 | BK15: 5 | BL15: 3 | BM15: 3 | BN15: 1 | BO15: 2 | BP15: 3 | BQ15: 5 | BR15: 4 | BS15: 6 | BT15: Scanned PDFs uploaded as images: my screen reader reads nothing, and the text-to-speech I use for dyslexia can't read them either. | BW15: =IF($R15="","",INDEX(Codes!$E$2:$E$108,MATCH("B1|"&$R15,Codes!$A$2:$A$108,0))) -> 5 | BX15: =IF($Y15="","",INDEX(Codes!$E$2:$E$108,MATCH("B4|"&$Y15,Codes!$A$2:$A$108,0))) -> 5 | BY15: =IF($I15="","",INDEX(Codes!$E$2:$E$108,MATCH("A7|"&$I15,Codes!$A$2:$A$108,0))) -> 3 | BZ15: =IF($AU15="","",INDEX(Codes!$E$2:$E$108,MATCH("B8|"&$AU15,Codes!$A$2:$A$108,0))) -> 2 | CA15: =IF($H15="","",INDEX(Codes!$E$2:$E$108,MATCH("A6|"&$H15,Codes!$A$2:$A$108,0))) -> 6 | CB15: =IF($X15="","",IF($X15="phone",1,0)) -> 0 | CC15: =IF($BC15="","",8-$BC15) -> 2 | CD15: S6 Access-First Learners | CE15: 2.59 | CF15: 0.625
A16: R015 | B16: 2026-09-09 03:06 | C16: bsc | D16: 25-29 | E16: male | F16: tshd | G16: eu | H16: 3 | I16: 9-16 | J16: 1 | K16: 0 | L16: 0 | M16: 0 | N16: 0 | O16: 0 | P16: 0 | Q16: 5 | R16: 4-6 | S16: 1 | T16: 0 | U16: 0 | V16: 1 | W16: 0 | X16: phone | Y16: 2-5 | Z16: 1 | AA16: 1 | AB16: 1 | AC16: 0 | AD16: 1 | AE16: 0 | AF16: 0 | AG16: 0 | AH16: 1 | AI16: 0 | AJ16: 0 | AK16: 0 | AL16: 0 | AM16: 1 | AN16: 0 | AO16: 0 | AP16: 1 | AQ16: 0 | AR16: 0 | AS16: 0 | AT16: push | AU16: 1 | AV16: 0 | AW16: 0 | AX16: 0 | AY16: 1 | AZ16: 1 | BA16: 0 | BB16: 5 | BC16: 2 | BD16: 5 | BE16: 6 | BF16: 3 | BG16: 4 | BH16: 4 | BI16: 6 | BJ16: 5 | BK16: 3 | BL16: 4 | BM16: 4 | BN16: 3 | BO16: 2 | BP16: 6 | BQ16: 4 | BR16: 5 | BS16: 1 | BT16: Wanted to see what is due this week across all my courses. The dashboard cards each show something different and the calendar only shows things the teacher put a date on. | BU16: Nothing specific. | BW16: =IF($R16="","",INDEX(Codes!$E$2:$E$108,MATCH("B1|"&$R16,Codes!$A$2:$A$108,0))) -> 4 | BX16: =IF($Y16="","",INDEX(Codes!$E$2:$E$108,MATCH("B4|"&$Y16,Codes!$A$2:$A$108,0))) -> 2 | BY16: =IF($I16="","",INDEX(Codes!$E$2:$E$108,MATCH("A7|"&$I16,Codes!$A$2:$A$108,0))) -> 2 | BZ16: =IF($AU16="","",INDEX(Codes!$E$2:$E$108,MATCH("B8|"&$AU16,Codes!$A$2:$A$108,0))) -> 1 | CA16: =IF($H16="","",INDEX(Codes!$E$2:$E$108,MATCH("A6|"&$H16,Codes!$A$2:$A$108,0))) -> 3 | CB16: =IF($X16="","",IF($X16="phone",1,0)) -> 1 | CC16: =IF($BC16="","",8-$BC16) -> 6 | CD16: S1 Deadline Sprinters | CE16: -2.239 | CF16: -0.635
A17: R016 | B17: 2026-09-09 04:04 | C17: bsc | D17: 17-20 | E17: female | F17: tshd | G17: eu | H17: 4 | I17: 1-8 | J17: 1 | K17: 0 | L17: 0 | M17: 0 | N17: 0 | O17: 0 | P17: 0 | Q17: 6 | R17: daily | S17: 1 | T17: 0 | U17: 0 | V17: 1 | W17: 0 | X17: phone | Y17: lt2 | Z17: 1 | AA17: 1 | AB17: 1 | AC17: 1 | AD17: 1 | AE17: 0 | AF17: 0 | AG17: 0 | AH17: 0 | AI17: 0 | AJ17: 0 | AK17: 0 | AL17: 1 | AM17: 0 | AN17: 1 | AO17: 0 | AP17: 0 | AQ17: 0 | AR17: 0 | AS17: 0 | AT17: push | AU17: 0 | AV17: 0 | AW17: 1 | AX17: 0 | AY17: 1 | AZ17: 1 | BA17: 0 | BB17: 5 | BC17: 3 | BD17: 6 | BE17: 6 | BF17: 2 | BG17: 2 | BH17: 5 | BI17: 7 | BJ17: 4 | BK17: 3 | BL17: 4 | BM17: 3 | BN17: 3 | BO17: 1 | BP17: 2 | BQ17: 4 | BR17: 5 | BS17: 6 | BT17: Notification said 'new comment on your submission'. I opened it, no comment visible. Had to open it on a laptop to see the feedback. | BU17: When the teacher replied to my comment on my submission I saw it immediately in the app. | BW17: =IF($R17="","",INDEX(Codes!$E$2:$E$108,MATCH("B1|"&$R17,Codes!$A$2:$A$108,0))) -> 5 | BX17: =IF($Y17="","",INDEX(Codes!$E$2:$E$108,MATCH("B4|"&$Y17,Codes!$A$2:$A$108,0))) -> 1 | BY17: =IF($I17="","",INDEX(Codes!$E$2:$E$108,MATCH("A7|"&$I17,Codes!$A$2:$A$108,0))) -> 1 | BZ17: =IF($AU17="","",INDEX(Codes!$E$2:$E$108,MATCH("B8|"&$AU17,Codes!$A$2:$A$108,0))) -> 0 | CA17: =IF($H17="","",INDEX(Codes!$E$2:$E$108,MATCH("A6|"&$H17,Codes!$A$2:$A$108,0))) -> 4 | CB17: =IF($X17="","",IF($X17="phone",1,0)) -> 1 | CC17: =IF($BC17="","",8-$BC17) -> 5 | CD17: S1 Deadline Sprinters | CE17: -3.233 | CF17: -0.566
A18: R017 | B18: 2026-09-09 09:09 | C18: bsc | D18: 21-24 | E18: female | F18: tls | G18: nl | H18: 4 | I18: 9-16 | J18: 1 | K18: 0 | L18: 0 | M18: 0 | N18: 0 | O18: 0 | P18: 0 | Q18: 7 | R18: daily | S18: 1 | T18: 0 | U18: 0 | V18: 1 | W18: 0 | X18: phone | Y18: lt2 | Z18: 1 | AA18: 1 | AB18: 1 | AC18: 0 | AD18: 0 | AE18: 0 | AF18: 0 | AG18: 1 | AH18: 0 | AI18: 0 | AJ18: 0 | AK18: 0 | AL18: 1 | AM18: 1 | AN18: 0 | AO18: 1 | AP18: 0 | AQ18: 0 | AR18: 0 | AS18: 0 | AT18: inapp | AU18: 1 | AV18: 0 | AW18: 1 | AX18: 0 | AY18: 1 | AZ18: 1 | BA18: 0 | BB18: 4 | BC18: 3 | BD18: 5 | BE18: 7 | BF18: 3 | BG18: 5 | BH18: 5 | BI18: 3 | BJ18: 5 | BK18: 5 | BL18: 5 | BM18: 3 | BN18: 4 | BO18: 1 | BP18: 3 | BQ18: 2 | BR18: 5 | BS18: 6 | BT18: I wanted to quickly check if the lecture was cancelled. Had to go dashboard > course > announcements > scroll. Three taps too many when you are on the bus. | BU18: Seeing the exact time left before a deadline on the assignment page. | BW18: =IF($R18="","",INDEX(Codes!$E$2:$E$108,MATCH("B1|"&$R18,Codes!$A$2:$A$108,0))) -> 5 | BX18: =IF($Y18="","",INDEX(Codes!$E$2:$E$108,MATCH("B4|"&$Y18,Codes!$A$2:$A$108,0))) -> 1 | BY18: =IF($I18="","",INDEX(Codes!$E$2:$E$108,MATCH("A7|"&$I18,Codes!$A$2:$A$108,0))) -> 2 | BZ18: =IF($AU18="","",INDEX(Codes!$E$2:$E$108,MATCH("B8|"&$AU18,Codes!$A$2:$A$108,0))) -> 1 | CA18: =IF($H18="","",INDEX(Codes!$E$2:$E$108,MATCH("A6|"&$H18,Codes!$A$2:$A$108,0))) -> 4 | CB18: =IF($X18="","",IF($X18="phone",1,0)) -> 1 | CC18: =IF($BC18="","",8-$BC18) -> 5 | CD18: S1 Deadline Sprinters | CE18: -3.206 | CF18: -2.275
A19: R018 | B19: 2026-09-09 09:22 | C19: msc | D19: 25-29 | E19: male | F19: tls | G19: nl | H19: 4 | I19: 9-16 | J19: 1 | K19: 0 | L19: 0 | M19: 0 | N19: 0 | O19: 0 | P19: 0 | Q19: 4 | R19: 4-6 | S19: 1 | T19: 0 | U19: 0 | V19: 1 | W19: 1 | X19: laptop | Y19: 5-15 | Z19: 1 | AA19: 1 | AB19: 0 | AC19: 1 | AD19: 1 | AE19: 0 | AF19: 1 | AG19: 1 | AH19: 1 | AI19: 1 | AJ19: 0 | AK19: 0 | AL19: 0 | AM19: 0 | AN19: 0 | AO19: 0 | AP19: 0 | AQ19: 1 | AR19: 0 | AS19: 1 | AT19: email | AU19: 1 | AV19: 1 | AW19: 0 | AX19: 1 | AY19: 0 | AZ19: 0 | BA19: 0 | BB19: 3 | BC19: 4 | BD19: 5 | BE19: 5 | BF19: 3 | BG19: 2 | BH19: 4 | BI19: 6 | BJ19: 6 | BK19: 2 | BL19: 4 | BM19: 4 | BN19: 1 | BO19: 3 | BP19: 4 | BQ19: 6 | BR19: 2 | BS19: 5 | BT19: Downloaded all the slides for Consumer Behaviour to make notes; every file had a different naming scheme, so sorting them in my notes app was manual work. | BU19: Downloading all files of a module in one zip. | BW19: =IF($R19="","",INDEX(Codes!$E$2:$E$108,MATCH("B1|"&$R19,Codes!$A$2:$A$108,0))) -> 4 | BX19: =IF($Y19="","",INDEX(Codes!$E$2:$E$108,MATCH("B4|"&$Y19,Codes!$A$2:$A$108,0))) -> 3 | BY19: =IF($I19="","",INDEX(Codes!$E$2:$E$108,MATCH("A7|"&$I19,Codes!$A$2:$A$108,0))) -> 2 | BZ19: =IF($AU19="","",INDEX(Codes!$E$2:$E$108,MATCH("B8|"&$AU19,Codes!$A$2:$A$108,0))) -> 1 | CA19: =IF($H19="","",INDEX(Codes!$E$2:$E$108,MATCH("A6|"&$H19,Codes!$A$2:$A$108,0))) -> 4 | CB19: =IF($X19="","",IF($X19="phone",1,0)) -> 0 | CC19: =IF($BC19="","",8-$BC19) -> 4 | CD19: S2 Structured Scholars | CE19: 0.704 | CF19: 1.077
A20: R019 | B20: 2026-09-09 09:34 | C20: msc | D20: 30-39 | E20: male | F20: tisem | G20: noneu | H20: 2 | I20: 0 | J20: 1 | K20: 0 | L20: 0 | M20: 0 | N20: 0 | O20: 0 | P20: 0 | Q20: 5 | R20: several | S20: 1 | T20: 0 | U20: 1 | V20: 0 | W20: 0 | X20: laptop | Y20: gt30 | Z20: 0 | AA20: 1 | AB20: 0 | AC20: 1 | AD20: 0 | AE20: 0 | AF20: 1 | AG20: 0 | AH20: 1 | AI20: 1 | AJ20: 1 | AK20: 0 | AL20: 1 | AM20: 0 | AN20: 0 | AO20: 0 | AP20: 0 | AQ20: 0 | AR20: 1 | AS20: 0 | AT20: inapp | AU20: 0 | AV20: 0 | AW20: 1 | AX20: 1 | AY20: 1 | AZ20: 1 | BA20: 0 | BB20: 1 | BC20: 7 | BD20: 3 | BE20: 5 | BF20: 5 | BG20: 3 | BH20: 4 | BI20: 5 | BJ20: 6 | BK20: 3 | BL20: 3 | BM20: 2 | BN20: 1 | BO20: 3 | BP20: 4 | BQ20: 6 | BR20: 2 | BS20: 5 | BT20: Modules is one long scroll. There is no overview of the course structure, no 'you are here' and no way to collapse everything with one click. | BV20: I use Notion for everything and Canvas is just the place where files live. | BW20: =IF($R20="","",INDEX(Codes!$E$2:$E$108,MATCH("B1|"&$R20,Codes!$A$2:$A$108,0))) -> 6 | BX20: =IF($Y20="","",INDEX(Codes!$E$2:$E$108,MATCH("B4|"&$Y20,Codes!$A$2:$A$108,0))) -> 5 | BY20: =IF($I20="","",INDEX(Codes!$E$2:$E$108,MATCH("A7|"&$I20,Codes!$A$2:$A$108,0))) -> 0 | BZ20: =IF($AU20="","",INDEX(Codes!$E$2:$E$108,MATCH("B8|"&$AU20,Codes!$A$2:$A$108,0))) -> 0 | CA20: =IF($H20="","",INDEX(Codes!$E$2:$E$108,MATCH("A6|"&$H20,Codes!$A$2:$A$108,0))) -> 2 | CB20: =IF($X20="","",IF($X20="phone",1,0)) -> 0 | CC20: =IF($BC20="","",8-$BC20) -> 1 | CD20: S2 Structured Scholars | CE20: 2.556 | CF20: 1.847
A21: R020 | B21: 2026-09-09 09:49 | C21: msc | D21: 17-20 | E21: female | F21: tsb | G21: eu | H21: 2 | I21: 0 | J21: 1 | K21: 0 | L21: 0 | M21: 0 | N21: 0 | O21: 0 | P21: 0 | Q21: 5 | R21: several | S21: 1 | T21: 0 | U21: 1 | V21: 0 | W21: 0 | X21: phone | Y21: 2-5 | Z21: 1 | AA21: 0 | AB21: 1 | AC21: 1 | AD21: 1 | AE21: 0 | AF21: 0 | AG21: 0 | AH21: 1 | AI21: 0 | AJ21: 0 | AK21: 0 | AL21: 0 | AM21: 0 | AN21: 0 | AO21: 0 | AP21: 0 | AQ21: 0 | AR21: 1 | AS21: 0 | AT21: push | AU21: 2-3 | AV21: 0 | AW21: 0 | AX21: 0 | AY21: 1 | AZ21: 0 | BA21: 0 | BB21: 3 | BC21: 4 | BD21: 4 | BE21: 6 | BF21: 5 | BG21: 4 | BH21: 5 | BI21: 7 | BJ21: 4 | BK21: 2 | BL21: 4 | BM21: 3 | BN21: 3 | BO21: 1 | BP21: 2 | BQ21: 4 | BR21: 5 | BS21: 6 | BT21: Tried to find the slides for last week on my phone. Modules is a giant list, you scroll for ages, and half the folders are named 'Week X' and half 'Lecture X'. | BU21: The To-do list saved me once: I had forgotten about a quiz and it was there. | BV21: Dark mode. | BW21: =IF($R21="","",INDEX(Codes!$E$2:$E$108,MATCH("B1|"&$R21,Codes!$A$2:$A$108,0))) -> 6 | BX21: =IF($Y21="","",INDEX(Codes!$E$2:$E$108,MATCH("B4|"&$Y21,Codes!$A$2:$A$108,0))) -> 2 | BY21: =IF($I21="","",INDEX(Codes!$E$2:$E$108,MATCH("A7|"&$I21,Codes!$A$2:$A$108,0))) -> 0 | BZ21: =IF($AU21="","",INDEX(Codes!$E$2:$E$108,MATCH("B8|"&$AU21,Codes!$A$2:$A$108,0))) -> 2 | CA21: =IF($H21="","",INDEX(Codes!$E$2:$E$108,MATCH("A6|"&$H21,Codes!$A$2:$A$108,0))) -> 2 | CB21: =IF($X21="","",IF($X21="phone",1,0)) -> 1 | CC21: =IF($BC21="","",8-$BC21) -> 4 | CD21: S1 Deadline Sprinters | CE21: -1.609 | CF21: -0.673
A22: R021 | B22: 2026-09-09 10:14 | C22: msc | D22: 21-24 | E22: female | F22: tshd | G22: noneu | H22: 2 | I22: 9-16 | J22: 0 | K22: 0 | L22: 0 | M22: 0 | N22: 0 | O22: 0 | P22: 1 | Q22: 5 | R22: daily | S22: 1 | T22: 0 | U22: 0 | V22: 1 | W22: 0 | X22: laptop | Y22: 5-15 | Z22: 1 | AA22: 1 | AB22: 1 | AC22: 1 | AD22: 1 | AE22: 0 | AF22: 0 | AG22: 0 | AH22: 1 | AI22: 0 | AJ22: 0 | AK22: 0 | AL22: 0 | AM22: 0 | AN22: 1 | AO22: 0 | AP22: 1 | AQ22: 1 | AR22: 1 | AS22: 0 | AT22: email | AU22: 0 | AV22: 0 | AW22: 1 | AX22: 1 | AY22: 0 | AZ22: 0 | BA22: 0 | BB22: 3 | BC22: 5 | BD22: 4 | BE22: 6 | BF22: 4 | BG22: 1 | BH22: 5 | BI22: 6 | BJ22: 5 | BK22: 4 | BL22: 3 | BM22: 4 | BN22: 1 | BO22: 3 | BP22: 4 | BQ22: 6 | BR22: 2 | BS22: 5 | BT22: The syllabus page was empty in 3 of my 4 courses. The actual course guide was a PDF somewhere in Files. | BU22: Having every submission I ever made in one place when I wrote my thesis. | BW22: =IF($R22="","",INDEX(Codes!$E$2:$E$108,MATCH("B1|"&$R22,Codes!$A$2:$A$108,0))) -> 5 | BX22: =IF($Y22="","",INDEX(Codes!$E$2:$E$108,MATCH("B4|"&$Y22,Codes!$A$2:$A$108,0))) -> 3 | BY22: =IF($I22="","",INDEX(Codes!$E$2:$E$108,MATCH("A7|"&$I22,Codes!$A$2:$A$108,0))) -> 2 | BZ22: =IF($AU22="","",INDEX(Codes!$E$2:$E$108,MATCH("B8|"&$AU22,Codes!$A$2:$A$108,0))) -> 0 | CA22: =IF($H22="","",INDEX(Codes!$E$2:$E$108,MATCH("A6|"&$H22,Codes!$A$2:$A$108,0))) -> 2 | CB22: =IF($X22="","",IF($X22="phone",1,0)) -> 0 | CC22: =IF($BC22="","",8-$BC22) -> 3 | CD22: S2 Structured Scholars | CE22: 1.014 | CF22: 1.616
A23: R022 | B23: 2026-09-09 11:29 | C23: phd | D23: 25-29 | E23: female | F23: tst | G23: nl | H23: 1 | I23: 0 | J23: 1 | K23: 0 | L23: 0 | M23: 0 | N23: 0 | O23: 0 | P23: 0 | Q23: 5 | R23: 4-6 | S23: 1 | T23: 0 | U23: 0 | V23: 1 | W23: 0 | X23: laptop | Y23: gt30 | Z23: 0 | AA23: 1 | AB23: 0 | AC23: 1 | AD23: 1 | AE23: 1 | AF23: 0 | AG23: 1 | AH23: 0 | AI23: 0 | AJ23: 0 | AK23: 0 | AL23: 0 | AM23: 0 | AN23: 0 | AO23: 0 | AP23: 0 | AQ23: 0 | AR23: 1 | AS23: 0 | AT23: push | AU23: 2-3 | AV23: 0 | AW23: 1 | AX23: 1 | AY23: 0 | AZ23: 0 | BA23: 0 | BB23: 3 | BC23: 6 | BD23: 2 | BE23: 4 | BF23: 5 | BG23: 3 | BH23: 4 | BI23: 5 | BJ23: 5 | BK23: 5 | BL23: 3 | BM23: 4 | BN23: 1 | BO23: 3 | BP23: 4 | BQ23: 6 | BR23: 2 | BS23: 5 | BT23: Annotating a PDF in the built-in viewer is impossible, and downloading each one separately to Zotero takes forever. | BW23: =IF($R23="","",INDEX(Codes!$E$2:$E$108,MATCH("B1|"&$R23,Codes!$A$2:$A$108,0))) -> 4 | BX23: =IF($Y23="","",INDEX(Codes!$E$2:$E$108,MATCH("B4|"&$Y23,Codes!$A$2:$A$108,0))) -> 5 | BY23: =IF($I23="","",INDEX(Codes!$E$2:$E$108,MATCH("A7|"&$I23,Codes!$A$2:$A$108,0))) -> 0 | BZ23: =IF($AU23="","",INDEX(Codes!$E$2:$E$108,MATCH("B8|"&$AU23,Codes!$A$2:$A$108,0))) -> 2 | CA23: =IF($H23="","",INDEX(Codes!$E$2:$E$108,MATCH("A6|"&$H23,Codes!$A$2:$A$108,0))) -> 1 | CB23: =IF($X23="","",IF($X23="phone",1,0)) -> 0 | CC23: =IF($BC23="","",8-$BC23) -> 2 | CD23: S2 Structured Scholars | CE23: 2.535 | CF23: 1.641
A24: R023 | B24: 2026-09-09 11:29 | C24: msc | D24: 21-24 | E24: male | F24: tsb | G24: eu | H24: 3 | I24: 1-8 | J24: 1 | K24: 0 | L24: 0 | M24: 0 | N24: 0 | O24: 0 | P24: 0 | Q24: 6 | R24: daily | S24: 0 | T24: 1 | U24: 0 | V24: 1 | W24: 0 | X24: desktop | Y24: 15-30 | Z24: 0 | AA24: 0 | AB24: 1 | AC24: 1 | AD24: 0 | AE24: 0 | AF24: 0 | AG24: 1 | AH24: 0 | AI24: 0 | AJ24: 0 | AK24: 0 | AL24: 0 | AM24: 0 | AN24: 0 | AO24: 0 | AP24: 1 | AQ24: 1 | AR24: 1 | AS24: 0 | AT24: email | AU24: 0 | AV24: 0 | AW24: 1 | AX24: 0 | AY24: 0 | AZ24: 0 | BA24: 0 | BB24: 3 | BC24: 5 | BD24: 4 | BE24: 5 | BF24: 2 | BG24: 2 | BH24: 3 | BI24: 4 | BJ24: 4 | BK24: 5 | BL24: 4 | BM24: 4 | BN24: 1 | BO24: 3 | BP24: 5 | BQ24: 4 | BR24: 2 | BS24: 6 | BT24: Discussions are a mess for seminar prep: threads collapse, and there's no way to see what changed since I last visited. | BU24: Having every submission I ever made in one place when I wrote my thesis. | BW24: =IF($R24="","",INDEX(Codes!$E$2:$E$108,MATCH("B1|"&$R24,Codes!$A$2:$A$108,0))) -> 5 | BX24: =IF($Y24="","",INDEX(Codes!$E$2:$E$108,MATCH("B4|"&$Y24,Codes!$A$2:$A$108,0))) -> 4 | BY24: =IF($I24="","",INDEX(Codes!$E$2:$E$108,MATCH("A7|"&$I24,Codes!$A$2:$A$108,0))) -> 1 | BZ24: =IF($AU24="","",INDEX(Codes!$E$2:$E$108,MATCH("B8|"&$AU24,Codes!$A$2:$A$108,0))) -> 0 | CA24: =IF($H24="","",INDEX(Codes!$E$2:$E$108,MATCH("A6|"&$H24,Codes!$A$2:$A$108,0))) -> 3 | CB24: =IF($X24="","",IF($X24="phone",1,0)) -> 0 | CC24: =IF($BC24="","",8-$BC24) -> 3 | CD24: S2 Structured Scholars | CE24: 1.143 | CF24: 1.02
A25: R024 | B25: 2026-09-09 11:53 | C25: lecturer | D25: 40-49 | E25: female | F25: tst | G25: nl | H25: 1 | I25: 0 | J25: 1 | K25: 0 | L25: 0 | M25: 0 | N25: 0 | O25: 0 | P25: 0 | Q25: 4 | R25: 2-3 | S25: 1 | T25: 1 | U25: 0 | V25: 0 | W25: 0 | X25: desktop | Y25: 5-15 | Z25: 0 | AA25: 1 | AB25: 0 | AC25: 0 | AD25: 0 | AE25: 0 | AF25: 0 | AG25: 0 | AH25: 0 | AI25: 0 | AJ25: 1 | AK25: 0 | AL25: 0 | AM25: 0 | AN25: 0 | AO25: 0 | AP25: 1 | AQ25: 1 | AR25: 1 | AS25: 0 | AT25: email | AU25: 2-3 | AV25: 0 | AW25: 1 | AX25: 0 | AY25: 1 | AZ25: 1 | BA25: 0 | BB25: 3 | BC25: 6 | BD25: 4 | BE25: 6 | BF25: 3 | BG25: 3 | BH25: 5 | BI25: 3 | BJ25: 6 | BK25: 5 | BL25: 2 | BM25: 2 | BN25: 2 | BO25: 1 | BP25: 5 | BQ25: 3 | BR25: 4 | BS25: 6 | BT25: Sending an announcement: I wrote it, clicked something and it disappeared. The second time I wrote it in Word first | BU25: Not much, it does the job. | BW25: =IF($R25="","",INDEX(Codes!$E$2:$E$108,MATCH("B1|"&$R25,Codes!$A$2:$A$108,0))) -> 3 | BX25: =IF($Y25="","",INDEX(Codes!$E$2:$E$108,MATCH("B4|"&$Y25,Codes!$A$2:$A$108,0))) -> 3 | BY25: =IF($I25="","",INDEX(Codes!$E$2:$E$108,MATCH("A7|"&$I25,Codes!$A$2:$A$108,0))) -> 0 | BZ25: =IF($AU25="","",INDEX(Codes!$E$2:$E$108,MATCH("B8|"&$AU25,Codes!$A$2:$A$108,0))) -> 2 | CA25: =IF($H25="","",INDEX(Codes!$E$2:$E$108,MATCH("A6|"&$H25,Codes!$A$2:$A$108,0))) -> 1 | CB25: =IF($X25="","",IF($X25="phone",1,0)) -> 0 | CC25: =IF($BC25="","",8-$BC25) -> 2 | CD25: S5 Reluctant Instructors | CE25: 1.753 | CF25: -1.743
A26: R025 | B26: 2026-09-09 11:59 | C26: phd | D26: 25-29 | E26: female | F26: tsb | G26: eu | H26: 2 | I26: 1-8 | J26: 1 | K26: 0 | L26: 0 | M26: 0 | N26: 0 | O26: 0 | P26: 0 | Q26: 7 | R26: daily | S26: 1 | T26: 0 | U26: 0 | V26: 0 | W26: 0 | X26: laptop | Y26: gt30 | Z26: 1 | AA26: 1 | AB26: 1 | AC26: 0 | AD26: 0 | AE26: 0 | AF26: 1 | AG26: 0 | AH26: 0 | AI26: 0 | AJ26: 0 | AK26: 0 | AL26: 0 | AM26: 1 | AN26: 0 | AO26: 1 | AP26: 1 | AQ26: 1 | AR26: 0 | AS26: 0 | AT26: inapp | AU26: 0 | AV26: 0 | AW26: 1 | AX26: 1 | AY26: 0 | AZ26: 0 | BA26: 0 | BB26: 2 | BC26: 4 | BD26: 2 | BE26: 5 | BF26: 4 | BG26: 2 | BH26: 5 | BI26: 6 | BJ26: 5 | BK26: 5 | BL26: 2 | BM26: 4 | BN26: 1 | BO26: 4 | BP26: 3 | BQ26: 6 | BR26: 2 | BS26: 5 | BT26: i wanted to re-watch the part of the Statistics 2 lecture about coding the interviews. No chapters, no transcript search, so I scrubbed through 90 minutes. | BU26: A discussion where the lecturer pinned the answers to common questions before the exam. | BV26: Consistency between courses would fix most of my problems. | BW26: =IF($R26="","",INDEX(Codes!$E$2:$E$108,MATCH("B1|"&$R26,Codes!$A$2:$A$108,0))) -> 5 | BX26: =IF($Y26="","",INDEX(Codes!$E$2:$E$108,MATCH("B4|"&$Y26,Codes!$A$2:$A$108,0))) -> 5 | BY26: =IF($I26="","",INDEX(Codes!$E$2:$E$108,MATCH("A7|"&$I26,Codes!$A$2:$A$108,0))) -> 1 | BZ26: =IF($AU26="","",INDEX(Codes!$E$2:$E$108,MATCH("B8|"&$AU26,Codes!$A$2:$A$108,0))) -> 0 | CA26: =IF($H26="","",INDEX(Codes!$E$2:$E$108,MATCH("A6|"&$H26,Codes!$A$2:$A$108,0))) -> 2 | CB26: =IF($X26="","",IF($X26="phone",1,0)) -> 0 | CC26: =IF($BC26="","",8-$BC26) -> 4 | CD26: S2 Structured Scholars | CE26: 1.677 | CF26: 3.097
A27: R026 | B27: 2026-09-09 12:44 | C27: msc | D27: 21-24 | E27: male | F27: tshd | G27: noneu | H27: 3 | I27: 1-8 | J27: 1 | K27: 0 | L27: 0 | M27: 0 | N27: 0 | O27: 0 | P27: 0 | Q27: 6 | R27: 4-6 | S27: 1 | T27: 0 | U27: 1 | V27: 1 | W27: 0 | X27: laptop | Y27: 15-30 | Z27: 1 | AA27: 1 | AB27: 0 | AC27: 1 | AD27: 1 | AE27: 0 | AF27: 1 | AG27: 1 | AH27: 1 | AI27: 1 | AJ27: 0 | AK27: 0 | AL27: 1 | AM27: 0 | AN27: 0 | AO27: 0 | AP27: 0 | AQ27: 0 | AR27: 0 | AS27: 0 | AT27: email | AU27: 0 | AV27: 0 | AW27: 1 | AX27: 1 | AY27: 1 | AZ27: 1 | BA27: 0 | BB27: 5 | BC27: 3 | BD27: 3 | BE27: 4 | BF27: 5 | BG27: 3 | BH27: 4 | BI27: 6 | BJ27: 5 | BK27: 2 | BL27: 4 | BM27: 3 | BN27: 1 | BO27: 3 | BP27: 4 | BQ27: 5 | BR27: 2 | BS27: 6 | BT27: Search in Canvas only searches the current course, and only some things. I wanted a formula from a slide two weeks ago and ended up opening every PDF. | BV27: Consistency between courses would fix most of my problems. | BW27: =IF($R27="","",INDEX(Codes!$E$2:$E$108,MATCH("B1|"&$R27,Codes!$A$2:$A$108,0))) -> 4 | BX27: =IF($Y27="","",INDEX(Codes!$E$2:$E$108,MATCH("B4|"&$Y27,Codes!$A$2:$A$108,0))) -> 4 | BY27: =IF($I27="","",INDEX(Codes!$E$2:$E$108,MATCH("A7|"&$I27,Codes!$A$2:$A$108,0))) -> 1 | BZ27: =IF($AU27="","",INDEX(Codes!$E$2:$E$108,MATCH("B8|"&$AU27,Codes!$A$2:$A$108,0))) -> 0 | CA27: =IF($H27="","",INDEX(Codes!$E$2:$E$108,MATCH("A6|"&$H27,Codes!$A$2:$A$108,0))) -> 3 | CB27: =IF($X27="","",IF($X27="phone",1,0)) -> 0 | CC27: =IF($BC27="","",8-$BC27) -> 5 | CD27: S2 Structured Scholars | CE27: 1.041 | CF27: 1.423
A28: R027 | B28: 2026-09-09 13:26 | C28: phd | D28: 21-24 | E28: male | F28: tshd | G28: eu | H28: 1 | I28: 0 | J28: 1 | K28: 0 | L28: 0 | M28: 0 | N28: 0 | O28: 0 | P28: 0 | Q28: 7 | R28: daily | S28: 1 | T28: 0 | U28: 0 | V28: 0 | W28: 1 | X28: laptop | Y28: 5-15 | Z28: 1 | AA28: 1 | AB28: 1 | AC28: 1 | AD28: 1 | AE28: 1 | AF28: 0 | AG28: 0 | AH28: 1 | AI28: 0 | AJ28: 0 | AK28: 0 | AL28: 1 | AM28: 0 | AN28: 0 | AO28: 0 | AP28: 0 | AQ28: 0 | AR28: 1 | AS28: 0 | AT28: off | AU28: 2-3 | AV28: 0 | AW28: 1 | AX28: 1 | AY28: 1 | AZ28: 0 | BA28: 0 | BB28: 3 | BC28: 5 | BD28: 5 | BE28: 3 | BF28: 3 | BG28: 1 | BH28: 4 | BI28: 7 | BJ28: 6 | BK28: 5 | BL28: 4 | BM28: 5 | BN28: 1 | BO28: 3 | BP28: 4 | BQ28: 5 | BR28: 2 | BS28: 6 | BT28: I keep a Notion page per course because the Canvas page for Cognitive Science has no structure I can rely on. | BU28: A discussion where the lecturer pinned the answers to common questions before the exam. | BV28: Please make lecturers date their assignments. | BW28: =IF($R28="","",INDEX(Codes!$E$2:$E$108,MATCH("B1|"&$R28,Codes!$A$2:$A$108,0))) -> 5 | BX28: =IF($Y28="","",INDEX(Codes!$E$2:$E$108,MATCH("B4|"&$Y28,Codes!$A$2:$A$108,0))) -> 3 | BY28: =IF($I28="","",INDEX(Codes!$E$2:$E$108,MATCH("A7|"&$I28,Codes!$A$2:$A$108,0))) -> 0 | BZ28: =IF($AU28="","",INDEX(Codes!$E$2:$E$108,MATCH("B8|"&$AU28,Codes!$A$2:$A$108,0))) -> 2 | CA28: =IF($H28="","",INDEX(Codes!$E$2:$E$108,MATCH("A6|"&$H28,Codes!$A$2:$A$108,0))) -> 1 | CB28: =IF($X28="","",IF($X28="phone",1,0)) -> 0 | CC28: =IF($BC28="","",8-$BC28) -> 3 | CD28: S2 Structured Scholars | CE28: 0.307 | CF28: 2.961
